<!-- Description: URDF file for the Single Rail Tripteron robot -->
<!-- Radians 90 degrees = 1.5708, 180 degrees = 3.1416, 270 degrees = 4.7124, 360 degrees = 6.2832. 60 degrees = 1.0472, 120 degrees = 2.0944, 240 degrees = 4.1888, 300 degrees = 5.2359 -->

<robot name="Tripteron">

<material name="red">
    <color rgba="1 0 0 1"/> <!-- Red -->
</material>

<material name="blue">
    <color rgba="0 0 1 1"/> <!-- Blue -->
</material>

<material name="green">
    <color rgba="0 1 0 1"/> <!-- Green -->
</material>

<material name="yellow">
    <color rgba="1 1 0 1"/> <!-- Yellow -->
</material>

<material name="orange">
    <color rgba="1 0.5 0 1"/> <!-- Orange -->
</material>



<!-- Base Link - 390mm Rail -->
<link name="base_link">
    <visual>
        <origin xyz="0 0 0.2" rpy="1.5708 0 1.5708"/>
        <geometry>
        <cylinder length="3.9" radius="0.05"/>
        </geometry>
        <material name="blue"/>
    </visual>
</link>

<!-- Link 1 - Left Most platform, slider mate to base link -->
<link name="link1">
    <visual>
        <origin xyz="0.5 0 0.3" rpy="0 0 0"/>
        <geometry>
        <box size="0.3 0.6 0.05"/>
        </geometry>
        <material name="red"/>
    </visual>
    <collision>
        <origin xyz="0.5 0 0.3" rpy="0 0 0"/>
        <geometry>
         <box size="0.3 0.6 0.05"/>
        </geometry>
    </collision>
</link>

<!-- Link 2 - Mid platform, slider mate to base link -->
<link name="link2">
    <visual>
        <origin xyz="0 0 0.3" rpy="0 0 0"/>
        <geometry>
        <box size="0.3 0.6 0.05"/>
        </geometry>
        <material name="green"/>
    </visual>
    <collision>
        <origin xyz="0 0 0.3" rpy="0 0 0"/>
        <geometry>
         <box size="0.3 0.6 0.05"/>
        </geometry>
    </collision>
</link>

<!-- Link 3 - Right Most platform, slider mate to base link -->
<link name="link3">
    <visual>
        <origin xyz="-0.5 0 0.3" rpy="0 0 0"/>
        <geometry>
        <box size="0.3 0.6 0.05"/>
        </geometry>
        <material name="yellow"/>
    </visual>
    <collision>
        <origin xyz="-0.5 0 0.3" rpy="0 0 0"/>
        <geometry>
         <box size="0.3 0.6 0.05"/>
        </geometry>
    </collision>
</link>

<!-- Link 4 - Left Most arm lower link -->
<link name="link4">
    <visual>
        <!-- Shift cylinder half its length downwards along z-axis -->
        <origin xyz="0 0 -0.6" rpy="0 0 0"/>
        <geometry>
            <cylinder length="1.2" radius="0.05"/>
        </geometry>
        <material name="red"/>
    </visual>
    <collision>
        <origin xyz="0 0 -0.6" rpy="0 0 0"/>
        <geometry>
            <cylinder length="1.2" radius="0.05"/>
        </geometry>
    </collision>
</link>

<!-- Link 5 - Right Most arm lower link -->
<link name="link5">
    <visual>
        <!-- Shift cylinder half its length downwards along z-axis -->
        <origin xyz="0 0 -0.6" rpy="0 0 0"/>
        <geometry>
            <cylinder length="1.2" radius="0.05"/>
        </geometry>
        <material name="yellow"/>
    </visual>
    <collision>
        <origin xyz="0 0 -0.6" rpy="0 0 0"/>
        <geometry>
            <cylinder length="1.2" radius="0.05"/>
        </geometry>
    </collision>
</link>


<!-- Link 6 - Center platform arm -->
<link name="link6">
    <visual>
        <!-- Shift cylinder half its length downwards along z-axis -->
        <origin xyz="0 0 -0.6" rpy="0 0 0"/>
        <geometry>
            <cylinder length="1.2" radius="0.05"/>
        </geometry>
        <material name="green"/>
    </visual>
    <collision>
        <origin xyz="0 0 -0.6" rpy="0 0 0"/>
        <geometry>
            <cylinder length="1.2" radius="0.05"/>
        </geometry>
    </collision>
</link>

<!-- Second Arms (lower arms) -->
<link name="link7">
    <visual>
        <origin xyz="0 0 -0.6" rpy="0 0 0"/>
        <geometry>
            <cylinder length="1.2" radius="0.04"/>
        </geometry>
        <material name="orange"/>
    </visual>
</link>

<link name="link8">
    <visual>
        <origin xyz="0 0 -0.6" rpy="0 0 0"/>
        <geometry>
            <cylinder length="1.2" radius="0.04"/>
        </geometry>
        <material name="orange"/>
    </visual>
</link>

<link name="link9">
    <visual>
        <origin xyz="0 0 -0.6" rpy="0 0 0"/>
        <geometry>
            <cylinder length="1.2" radius="0.04"/>
        </geometry>
        <material name="orange"/>
    </visual>
</link>








<!-- Joint 1 - 1st slider Joint -->
<joint name="joint1" type="prismatic">
    <origin xyz="0 0 0" rpy="0 0 0"/>
    <parent link="base_link"/>
    <child link="link1"/>
    <axis xyz="1 0 0"/>
    <limit lower="-1.95" upper="1.95"/>
</joint>

<!-- Joint 2 - 2nd slider Joint -->
<joint name="joint2" type="fixed">
    <origin xyz="0 0 0" rpy="0 0 0"/>
    <parent link="base_link"/>
    <child link="link2"/>
    <axis xyz="1 0 0"/>
    <limit lower="-1.95" upper="1.95"/>
</joint>

<!-- Joint 3 - 3rd slider Joint -->
<joint name="joint3" type="prismatic">
    <origin xyz="0 0 0" rpy="0 0 0"/>
    <parent link="base_link"/>
    <child link="link3"/>
    <axis xyz="1 0 0"/>
    <limit lower="-1.95" upper="1.95"/>
</joint>

<!-- Joint 4 - 1st Revolute Joint -->
<joint name="joint4" type="revolute">
    <origin xyz="0.5 0 0.3" rpy="1.4 0 0"/>
    <parent link="link1"/>
    <child link="link4"/>
    <axis xyz="1 1 0"/>
    <limit lower="0" upper="6.2832"/>
</joint>

<!-- Joint 5 - Right platform revolute joint -->
<joint name="joint5" type="revolute">
    <origin xyz="-0.5 0 0.3" rpy="1.0472 0 0"/>
    <parent link="link3"/>
    <child link="link5"/>
    <axis xyz="1 -1 0"/> <!-- mirror symmetric to link4 axis -->
    <limit lower="0" upper="6.2832"/>
</joint>

<!-- Joint 6 - Middle platform revolute joint (50 degrees offset in YZ plane) -->
<joint name="joint6" type="revolute">
    <origin xyz="0 0 0.3" rpy="0 0 0.8727 "/>
    <parent link="link2"/>
    <child link="link6"/>
    <axis xyz="1 0 0"/>
    <limit lower="-3.1416" upper="3.1416"/>
</joint>

<!-- Joints attaching second arms to first arms -->
<joint name="joint7" type="revolute">
    <origin xyz="0 0 -1.2" rpy="0 0 0"/>
    <parent link="link4"/>
    <child link="link7"/>
    <axis xyz="1 0 0"/>
    <limit lower="-3.1416" upper="3.1416"/>
</joint>

<joint name="joint8" type="revolute">
    <origin xyz="0 0 -1.2" rpy="0 0 0"/>
    <parent link="link5"/>
    <child link="link8"/>
    <axis xyz="1 0 0"/>
    <limit lower="-3.1416" upper="3.1416"/>
</joint>

<joint name="joint9" type="revolute">
    <origin xyz="0 0 -1.2" rpy="0 0 0"/>
    <parent link="link6"/>
    <child link="link9"/>
    <axis xyz="1 0 0"/>
    <limit lower="-3.1416" upper="3.1416"/>
</joint>



</robot>